Workbook

Sheet Ambas EDAR
E3: Valores límites | K3: Caudales mensuales en m3 | N3: Caudales en m3/d | S3: Parámetros de entrada según diseño
E4: Parámetros | H4: EDARI Cerceda - Cobelans | I4: EDAR VEDRA | K4: Mes | L4: EDARI Cerceda - Cobelans | M4: EDAR VEDRA | N4: EDARI Cerceda - Cobelans | O4: EDAR VEDRA | S4: Componente | T4: Unidad | U4: Cerceda | V4: Vedra
S5: Qm | T5: m3/h | U5: 198 | V5: 5.26
E6: DBO5 | G6: (mg/L) | H6: 25 | I6: 25 | K6: 1. -24 | L6: 16868 | M6: 652 | N6: =L6/31 -> 544.12903 | O6: =M6/31 -> 21.032258 | S6: Qmax | T6: m3/h | U6: 600 | V6: 15.15
E7: DQO | G7: (mg/L) | H7: 125 | I7: 125 | K7: 2. -24 | L7: 18759 | M7: 641 | N7: =L7/29 -> 646.86207 | O7: =M7/29 -> 22.103448 | S7: DBO5 | T7: kg/d | U7: 1425 | V7: 30
E8: SST | G8: (mg/L) | H8: 35 | I8: 35 | K8: 3. -24 | L8: 20556 | M8: 846 | N8: =L8/31 -> 663.09677 | O8: =M8/31 -> 27.290323 | S8: DQO | T8: kg/d | U8: – | V8: 67.5
E9: NT | G9: (mg/L) | H9: 15 | I9: 15 | K9: 4. -24 | L9: 13190 | M9: 451 | N9: =L9/30 -> 439.66667 | O9: =M9/30 -> 15.033333 | S9: SS | T9: kg/d | U9: 1710 | V9: 45
E10: PT | G10: (mg/L) | H10: 2 | I10: 2 | K10: 5. -24 | L10: 17228 | M10: 515 | N10: =L10/31 -> 555.74194 | O10: =M10/31 -> 16.612903 | S10: NT | T10: kg/d | U10: 285 | V10: 5.1
E11: pH | G11: (ud.pH) | H11: 5.5 - 9.5 | I11: 5.5 - 9.5 | K11: 6. -24 | L11: 11596 | M11: 376 | N11: =L11/30 -> 386.53333 | O11: =M11/30 -> 12.533333 | S11: PT | T11: kg/d | U11: 76 | V11: 1.3
E12: Amoniaco | G12: (mg/L) | H12: 2 | I12: --- | K12: 7. -24 | L12: 12347 | M12: 299 | N12: =L12/31 -> 398.29032 | O12: =M12/31 -> 9.6451613 | S12: A y G | T12: kg/d | U12: – | V12: 3.2
E13: Aceites y grasas | G13: (mg/L) | H13: --- | I13: 25 | K13: 8. -24 | L13: 12114 | M13: 198 | N13: =L13/31 -> 390.77419 | O13: =M13/31 -> 6.3870968 | S13: Det. Anion. | T13: kg/d | U13: – | V13: 0.4
E14: Detergentes aniónicos | G14: (mg/L) | H14: --- | I14: 3 | K14: 9. -24 | L14: 10654 | M14: --- | N14: =L14/30 -> 355.13333 | O14: ---
E15: Coliformes totales | G15: (NMP/100ml) | H15: 500 | I15: 500 | K15: 10. -24 | L15: 22561 | M15: --- | N15: =L15/31 -> 727.77419 | O15: ---
E16: Coliformes fecales | G16: (NMP/100ml) | H16: 100 | I16: 100 | K16: 11. -24 | L16: 9963 | M16: 485 | N16: =L16/30 -> 332.1 | O16: =M16/30 -> 16.166667
E17: Escherichia coli | G17: (NMP/100ml) | H17: 100 | I17: --- | K17: 12. -24 | L17: 11633 | M17: 523 | N17: =L17/31 -> 375.25806 | O17: =M17/31 -> 16.870968
C19: EDAR de Cerceda – Cobelans | L19: EDAR de Vedra
M22: Entrada Vedra (según diseño)
D23: Entrada Cerceda (según diseño) | M23: Componente | N23: Valor | O23: Unidad
D24: Componente | E24: Valor | F24: Unidad | M24: Qm | N24: 5.26 | O24: m3/h
D25: Qm | E25: 198 | F25: m3/h | M25: Qmax | N25: 15.15 | O25: m3/h
D26: Qmax | E26: 600 | F26: m3/h | M26: DBO5 | N26: 30 | O26: kg/d
D27: DBO5 | E27: 1425 | F27: kg/d | M27: DQO | N27: 67.5 | O27: kg/d
D28: SS | E28: 1710 | F28: kg/d | M28: SS | N28: 45 | O28: kg/d
D29: NT | E29: 285 | F29: kg/d | M29: NT | N29: 5.1 | O29: kg/d
D30: PT | E30: 76 | F30: kg/d | M30: PT | N30: 1.3 | O30: kg/d
M31: A y G | N31: 3.2 | O31: kg/d
M32: Det. Anion. | N32: 0.4 | O32: kg/d
C34: Salida Cerceda (según diseño) | L34: Salida Vedra (según diseño)
C35: Componente | D35: Valor | E35: Unidad | F35: Conversión de unidades | L35: Componente | M35: Valor | N35: Unidad | O35: Conversión de unidades
C36: Qm | D36: 198 | E36: m3/h | F36: – | G36: – | L36: Qm | M36: =N24 -> 5.26 | N36: m3/h | O36: – | P36: –
C37: Qmax | D37: 627 | E37: m3/h | F37: – | G37: – | L37: Qmax | M37: =N25 -> 15.15 | N37: m3/h | O37: – | P37: –
C38: DBO5 | D38: 25 | E38: mg/L | F38: =D38*$D$36*24/1000 -> 118.8 | G38: kg/d | L38: DBO5 | M38: =I6 -> 25 | N38: mg/L | O38: =M38 * (1000) * (1/1000000) * $M$36 * (24) -> 3.156 | P38: kg/d
C39: SS | D39: 35 | E39: mg/L | F39: =D39*$D$36*24/1000 -> 166.32 | G39: kg/d | L39: DQO | M39: =I7 -> 125 | N39: mg/L | O39: =M39 * (1000) * (1/1000000) * $M$36 * (24) -> 15.78 | P39: kg/d
C40: Amoniaco | D40: 2 | E40: mg/L | F40: =D40*$D$36*24/1000 -> 9.504 | G40: kg/d | L40: SS | M40: =I8 -> 35 | N40: mg/L | O40: =M40 * (1000) * (1/1000000) * $M$36 * (24) -> 4.4184 | P40: kg/d
C41: NT | D41: 15 | E41: mg/L | F41: =D41*$D$36*24/1000 -> 71.28 | G41: kg/d | L41: NT | M41: =I9 -> 15 | N41: mg/L | O41: =M41 * (1000) * (1/1000000) * $M$36 * (24) -> 1.8936 | P41: kg/d
C42: PT | D42: 2 | E42: mg/L | F42: =D42*$D$36*24/1000 -> 9.504 | G42: kg/d | L42: PT | M42: =I10 -> 2 | N42: mg/L | O42: =M42 * (1000) * (1/1000000) * $M$36 * (24) -> 0.25248 | P42: kg/d
L43: A y G | M43: =I13 -> 25 | N43: mg/L | O43: =M43 * (1000) * (1/1000000) * $M$36 * (24) -> 3.156 | P43: kg/d
L44: Det. Anion. | M44: =I14 -> 3 | N44: mg/L | O44: =M44 * (1000) * (1/1000000) * $M$36 * (24) -> 0.37872 | P44: kg/d
F46: UNIDADES FUNCIONALES
C49: kg de PO4 equivalente / kg de sustancia | G49: Carga de fosfato equivalente
...

Sheet Cerceda tabla
B2: Valores límites | J2: Caudales en m3
B3: Parámetros | E3: EDARI Cerceda - Cobelans | F3: EDAR VEDRA | J3: Mes | K3: EDAR CERCEDA
B5: DBO5 | D5: (mg/L) | E5: 25 | F5: 25 | J5: 1. -24 | K5: ='Ambas EDAR'!L6 -> 16868
B6: DQO | D6: (mg/L) | E6: 125 | F6: 125 | J6: 2. -24 | K6: ='Ambas EDAR'!L7 -> 18759
B7: SST | D7: (mg/L) | E7: 35 | F7: 35 | J7: 3. -24 | K7: ='Ambas EDAR'!L8 -> 20556
B8: NT | D8: (mg/L) | E8: 15 | F8: 15 | J8: 4. -24 | K8: ='Ambas EDAR'!L9 -> 13190
B9: PT | D9: (mg/L) | E9: 2 | F9: 2 | J9: 5. -24 | K9: ='Ambas EDAR'!L10 -> 17228
B10: pH | D10: (ud.pH) | E10: 5.5 - 9.5 | F10: 5.5 - 9.5 | J10: 6. -24 | K10: ='Ambas EDAR'!L11 -> 11596
B11: Amoniaco | D11: (mg/L) | E11: 2 | F11: --- | J11: 7. -24 | K11: ='Ambas EDAR'!L12 -> 12347
B12: Aceites y grasas | D12: (mg/L) | E12: --- | F12: 25 | J12: 8. -24 | K12: ='Ambas EDAR'!L13 -> 12114
B13: Detergentes aniónicos | D13: (mg/L) | E13: --- | F13: 3 | J13: 9. -24 | K13: ='Ambas EDAR'!L14 -> 10654
B14: Coliformes totales | D14: (NMP/100ml) | E14: 500 | F14: 500 | J14: 10. -24 | K14: ='Ambas EDAR'!L15 -> 22561
B15: Coliformes fecales | D15: (NMP/100ml) | E15: 100 | F15: 100 | J15: 11. -24 | K15: ='Ambas EDAR'!L16 -> 9963
B16: Escherichia coli | D16: (NMP/100ml) | E16: 100 | F16: --- | J16: 12. -24 | K16: ='Ambas EDAR'!L17 -> 11633
B20: PARÁMETROS DE ENTRADA DE LA EDARI CERCEDA-COBELANS
B21: Parámetros | C21: Unidades | D21: 1.24 | E21: 2.24 | F21: 3.24 | G21: 4.24 | H21: 5.24 | I21: 6.24 | J21: 7.24 | K21: 8.24 | L21: 9.24 | M21: 10.24 | N21: 11.24 | O21: 12.24 | P21: MEDIA
B22: DBO5 | C22: mg/L | D22: 81 | E22: 53 | F22: 32 | G22: 318 | H22: 53 | I22: 184 | J22: 148 | K22: 301 | L22: 47 | M22: 252 | N22: 50 | O22: 135 | P22: =AVERAGE(D22:O22) -> 137.83333
B23: DQO | C23: mg/L | D23: 300 | E23: 232 | F23: 54 | G23: 1500 | H23: 144 | I23: 336 | J23: 256 | K23: 600 | L23: 90 | M23: 400 | N23: 2830 | O23: 171 | P23: =AVERAGE(D23:O23) -> 576.08333
B24: SST | C24: mg/L | D24: 106.4 | E24: 115.7 | F24: 21.6 | G24: 500 | H24: 18.9 | I24: 43.6 | J24: 96.8 | K24: 103.8 | L24: 26.7 | M24: 78.2 | N24: 1910 | O24: 42 | P24: =AVERAGE(D24:O24) -> 255.30833
B25: NT | C25: mg/L | D25: 11.2 | E25: 10 | F25: 9.4 | G25: 72 | H25: 5.9 | I25: 19.2 | J25: 52.8 | K25: 42.6 | L25: 6.4 | M25: 31 | N25: 91.8 | O25: 17.9 | P25: =AVERAGE(D25:O25) -> 30.85
B26: PT | C26: mg/L | D26: 1.3 | E26: 2.3 | F26: 1.3 | G26: 19.9 | H26: 0.5 | I26: 1.3 | J26: 4 | K26: 4.7 | L26: 0.5 | M26: 0.8 | N26: 18.96 | O26: 2.27 | P26: =AVERAGE(D26:O26) -> 4.8191667
B27: pH | C27: ud. pH | D27: 6.5 | E27: 6.8 | F27: 6.8 | G27: 6.7 | H27: 6.5 | I27: 7 | J27: 7.3 | K27: 7.4 | L27: 6.6 | M27: 6.9 | N27: 6.6 | O27: 6.7 | P27: =AVERAGE(D27:O27) -> 6.8166667
B28: A y G | C28: mg/L | D28: 14.6 | E28: 14 | F28: 14 | G28: 14 | H28: 13.5 | I28: 25.8 | J28: 7.1 | K28: 61 | L28: 5 | M28: 5 | N28: 1.4 | O28: 0.86 | P28: =AVERAGE(D28:O28) -> 14.688333
B29: Det. Anion. | C29: mg/L | D29: 1.2 | E29: 0.6 | F29: 0.9 | G29: 9.2 | H29: 0.7 | I29: 2.7 | J29: 2 | K29: 4.2 | L29: 1.2 | M29: 1.7 | N29: 0.2 | O29: 0.2 | P29: =AVERAGE(D29:O29) -> 2.0666667
B30: DBO5 / DQO | C30: [ - ] | D30: =D22/D23 -> 0.27 | E30: =E22/E23 -> 0.22844828 | F30: =F22/F23 -> 0.59259259 | G30: =G22/G23 -> 0.212 | H30: =H22/H23 -> 0.36805556 | I30: =I22/I23 -> 0.54761905 | J30: =J22/J23 -> 0.578125 | K30: =K22/K23 -> 0.50166667 | ... O30: =O22/O23 -> 0.78947368 | P30: =AVERAGE(D30:O30) -> 0.43815591
B31: SST * 1.42 | C31: mg/L | D31: =D24*1.42 -> 151.088 | E31: =E24*1.42 -> 164.294 | F31: =F24*1.42 -> 30.672 | G31: =G24*1.42 -> 710 | H31: =H24*1.42 -> 26.838 | I31: =I24*1.42 -> 61.912 | J31: =J24*1.42 -> 137.456 | K31: =K24*1.42 -> 147.396 | ... O31: =O24*1.42 -> 59.64 | P31: =AVERAGE(D31:O31) -> 362.53783
B32: SST / DQO | C32: [ - ] | D32: =D24/D23 -> 0.35466667 | E32: =E24/E23 -> 0.4987069 | F32: =F24/F23 -> 0.4 | G32: =G24/G23 -> 0.33333333 | H32: =H24/H23 -> 0.13125 | I32: =I24/I23 -> 0.1297619 | J32: =J24/J23 -> 0.378125 | K32: =K24/K23 -> 0.173 | ... O32: =O24/O23 -> 0.24561404 | P32: =AVERAGE(D32:O32) -> 0.31762801
B33: SST / DBO5 | C33: [ - ] | D33: =D24/D22 -> 1.3135802 | E33: =E24/E22 -> 2.1830189 | F33: =F24/F22 -> 0.675 | G33: =G24/G22 -> 1.572327 | H33: =H24/H22 -> 0.35660377 | I33: =I24/I22 -> 0.23695652 | J33: =J24/J22 -> 0.65405405 | K33: =K24/K22 -> 0.3448505 | ... O33: =O24/O22 -> 0.31111111 | P33: =AVERAGE(D33:O33) -> 3.8938254
D35: Los datos que están en naranjo son inciertos, pues en las tablas recibidas aparecen como desigualdades en lugar de valores certeros.
D36: El 10.24 tengo una DQO muy alta, pero muy baja DBO. Esto puede deberse a que en el momento en que se tomó la muestra, estaba entrando principalmente agua industrial. El agua de las industrias es del polígono de acevedo, en donde es de destacar la presencia de
D38: =D22/D25 -> 7.2321429 | E38: =E22/E25 -> 5.3 | F38: =F22/F25 -> 3.4042553 | G38: =G22/G25 -> 4.4166667 | H38: =H22/H25 -> 8.9830508 | I38: =I22/I25 -> 9.5833333 | J38: =J22/J25 -> 2.8030303 | K38: =K22/K25 -> 7.0657277 | ... O38: =O22/O25 -> 7.5418994 | P38: =AVERAGE(D38:O38) -> 6.0289626
B40: PARÁMETROS DE SALIDA DE LA EDARI CERCEDA-COBELANS
B41: Parámetros | C41: Unidades | D41: 1.24 | E41: 2.24 | F41: 3.24 | G41: 4.24 | H41: 5.24 | I41: 6.24 | J41: 7.24 | K41: 8.24 | L41: 9.24 | M41: 10.24 | N41: 11.24 | O41: 12.24 | P41: MEDIA
B42: DBO5 | C42: mg/L | D42: 15 | E42: 15 | F42: 15 | G42: 15 | H42: 4 | I42: 6 | J42: 9 | K42: 7 | L42: 8 | M42: 10 | N42: 5 | O42: 5 | P42: =AVERAGE(D42:O42) -> 9.5
B43: DQO | C43: mg/L | D43: 20 | E43: 20 | F43: 20 | G43: 20 | H43: 14 | I43: 18 | J43: 22 | K43: 23 | L43: 30 | M43: 46 | N43: 30 | O43: 10 | P43: =AVERAGE(D43:O43) -> 22.75
B44: SST | C44: mg/L | D44: 5 | E44: 7.6 | F44: 5 | G44: 5 | H44: 2 | I44: 2 | J44: 2 | K44: 20.5 | L44: 15 | M44: 9.7 | N44: 15 | O44: 6 | P44: =AVERAGE(D44:O44) -> 7.9
B45: NT | C45: mg/L | D45: 5 | E45: 5 | F45: 5 | G45: 5 | H45: 1.9 | I45: 2.2 | J45: 2.1 | K45: 2.8 | L45: 3.3 | M45: 2.4 | N45: 3.8 | O45: 3 | P45: =AVERAGE(D45:O45) -> 3.4583333
B46: PT | C46: mg/L | D46: 0.5 | E46: 0.4 | F46: 0.8 | G46: 0.4 | H46: 0.5 | I46: 0.7 | J46: 0.7 | K46: 1.9 | L46: 1.5 | M46: 2 | N46: 0.8 | O46: 1.34 | P46: =AVERAGE(D46:O46) -> 0.96166667
B47: pH | C47: ud. pH | D47: 6.6 | E47: 7 | F47: 6.8 | G47: 6.8 | H47: 7 | I47: 7.1 | J47: 7.3 | K47: 7.3 | L47: 7.2 | M47: 6.8 | N47: 6.8 | O47: 7 | P47: =AVERAGE(D47:O47) -> 6.975
B48: Amoniaco | C48: mg/L | D48: 0.5 | E48: 0.57 | F48: 1.54 | G48: 0.5 | H48: 0.42 | I48: 0.31 | J48: 0.62 | K48: 0.32 | L48: 0.46 | M48: 0.45 | N48: --- | O48: 0.76 | P48: =AVERAGE(D48:O48) -> 0.58636364
...

Sheet Cerceda Balance
BD2: h | BE2: min
BD3: d | BE3: h
AO5: =24*366 -> 8784 | BA5: =BA17/31 -> 2.1470968 | BB5: =BA5*60/24 -> 5.3677419 | BI5: =AZ17/31 -> 24.110323
AA6: Caudales en m3/d | AE6: Consumos eléctricos anuales
AA7: ='Ambas EDAR'!K6 -> 1. -24 | AB7: ='Ambas EDAR'!N6 -> 544.12903 | AE7: Equipo | AG7: Cantidad | AH7: Potencia [kW] | AI7: t de operación [h/año] | AK7: Consumo anual [kWh] | AR7: EDAR CERCEDA COBELANS - HORAS DE EQUIPOS (horas/mes)
AA8: ='Ambas EDAR'!K7 -> 2. -24 | AB8: ='Ambas EDAR'!N7 -> 646.86207 | AE8: E.T.1 | AF8: Bombas sumergibles en agua bruta | AG8: 3 | AH8: 3.1 | AI8: 0 | AK8: =AH8*AI8 -> 0 | AM8: Tanque de homogeneización | AR8: BBA EXCESO 1 | AS8: BBA EXCESO 2 | AT8: BBA REC FANGOS 1 | AU8: BBA REC FANGOS 2 | AV8: BBA REC FANGOS 3 | AW8: SOPLANTE 1 | AX8: SOPLANTE 2 | AY8: AGIT ANAER. 1 | AZ8: AGIT ANAER. 2 | BA8: ROTOR 1 | BB8: ROTOR 2 | BC8: ROTOR 3 | BD8: ROTOTR 4 | BE8: ROTOR 5 | BF8: ROTOR 6 | BG8: ROTOR 7 | BH8: ROTOR 8 | BI8: AGIT AEROBIO 1 | BJ8: AGIT AEROBIO 2 | BK8: AGIT AEROBIO 3 | BL8: AGIT AEROBIO 4 | BM8: BBA INTERNO 1 | BN8: BBA INTERNO 2 | BO8: BBA FANGO A PREDESH | BP8: PREDESHIDRATADOR | BQ8: CENTRIFUGA | BR8: BBA FANGOS DESH
AA9: ='Ambas EDAR'!K8 -> 3. -24 | AB9: ='Ambas EDAR'!N8 -> 663.09677 | AE9: E.T.1 | AF9: Bombas de fangos en exceso | AG9: 2 | AH9: 1.3 | AI9: =SUM(AR10:AS21) -> 56.52 | AK9: =AH9*AI9 -> 73.476 | AM9: Bombeo de fangos
AA10: ='Ambas EDAR'!K9 -> 4. -24 | AB10: ='Ambas EDAR'!N9 -> 439.66667 | AE10: E.T.1 | AF10: Bombas de recirculación de fangos | AG10: 3 | AH10: 3.1 | AI10: =SUM(AT10:AV21) -> 2364.86 | AK10: =AH10*AI10 -> 7331.066 | AM10: Bombeo de fangos | AQ10: 1.24 | AR10: 5.1 | AS10: 5 | AT10: 73.92 | AU10: 74.49 | AV10: 74.16 | AW10: 374.4 | AX10: 375.98 | AY10: 721.49 | AZ10: 721.49 | BA10: 26.96 | BB10: 43.41 | BC10: 37.81 | BD10: 23.91 | BE10: 37.91 | BF10: 33.35 | BG10: 29.04 | BH10: 24.74 | BI10: 305.98 | BJ10: 305.98 | BK10: 311.29 | BL10: 311.27 | BM10: 170.92 | BN10: 395.36 | BO10: 10.04 | BP10: 36.75 | BQ10: 37.49 | BR10: 35.13
AA11: ='Ambas EDAR'!K10 -> 5. -24 | AB11: ='Ambas EDAR'!N10 -> 555.74194 | AE11: E.T.2 | AF11: Tamiz automático | AG11: 2 | AH11: 1.5 | AQ11: 2.24 | AR11: 2.65 | AS11: 3.01 | AT11: 82.29 | AU11: 82.03 | AV11: 82.7 | AW11: 345.73 | AX11: 345.82 | AY11: 721.49 | AZ11: 721.49 | BA11: 0 | BB11: 0 | BC11: 0 | BD11: 0 | BE11: 0 | BF11: 0 | BG11: 0 | BH11: 0 | BI11: 275.69 | BJ11: 275.69 | BK11: 278.65 | BL11: 278.65 | BM11: 264.01 | BN11: 364.09 | BO11: 5.64 | BP11: 23.01 | BQ11: 19.35 | BR11: 22.41 | BT11: Por qué los rotores no funcionaron en febrero?
AA12: ='Ambas EDAR'!K11 -> 6. -24 | AB12: ='Ambas EDAR'!N11 -> 386.53333 | AE12: E.T.3 | AF12: Puente desarenador / desengrasador | AG12: 4 | AH12: 1.1 | AQ12: 3.24 | AR12: 2.99 | AS12: 3.01 | AT12: 90.82 | AU12: 90.84 | AV12: 91.15 | AW12: 37.82 | AX12: 369.67 | AY12: 741.05 | AZ12: 741.05 | BA12: 32 | BB12: 29.59 | BC12: 25.65 | BD12: 22.82 | BE12: 28.83 | BF12: 25.83 | BG12: 22.85 | BH12: 19.98 | BI12: 288.42 | BJ12: 288.42 | BK12: 294.7 | BL12: 294.7 | BM12: 234.29 | BN12: 195.88 | BO12: 6.74 | BP12: 21.97 | BQ12: 21.89 | BR12: 22.42
AA13: ='Ambas EDAR'!K12 -> 7. -24 | AB13: ='Ambas EDAR'!N12 -> 398.29032 | AE13: E.T.4 | AF13: Vertedero automático | AG13: 2 | AH13: 0.75 | AQ13: 4.24 | AR13: 4.94 | AS13: 4.77 | AT13: 58.06 | AU13: 57.99 | AV13: 57.24 | AW13: 359.74 | AX13: 359.99 | AY13: 720.25 | AZ13: 720.25 | BA13: 33.2 | BB13: 37.32 | BC13: 33.2 | BD13: 24.16 | BE13: 32.76 | BF13: 29.47 | BG13: 26.33 | BH13: 23.2 | BI13: 273.62 | BJ13: 273.63 | BK13: 280.38 | BL13: 280.38 | BM13: 295.51 | BN13: 231.75 | BO13: 8.88 | BP13: 29.62 | BQ13: 30.22 | BR13: 34.63
AA14: ='Ambas EDAR'!K13 -> 8. -24 | AB14: ='Ambas EDAR'!N13 -> 390.77419 | AE14: E.T.5 | AF14: Extractor de arenas | AG14: 1 | AH14: 0.37 | AQ14: 5.24 | AR14: 0 | AS14: 0.01 | AT14: 73.98 | AU14: 74 | AV14: 73.87 | AW14: 384.78 | AX14: 363.99 | AY14: 734.55 | AZ14: 734.55 | BA14: 62.67 | BB14: 60.02 | BC14: 55.6 | BD14: 52.15 | BE14: 37.08 | BF14: 33.49 | BG14: 29.88 | BH14: 26.52 | BI14: 279.27 | BJ14: 279.26 | BK14: 284.4 | BL14: 284.4 | BM14: 165.99 | BN14: 540.26 | BO14: 0 | BP14: 0 | BQ14: 0 | BR14: 0 | BT14: Por qué no se deshidrataron lodos en mayo? Tampoco se bombearon fangos en exceso. será que no hubo casi producción de fangos por algún problema en el biológico? Se recirculó más fango que lo normal
AA15: ='Ambas EDAR'!K14 -> 9. -24 | AB15: ='Ambas EDAR'!N14 -> 355.13333 | AE15: E.T.6 | AF15: Soplantes | AG15: 2 | AH15: 5.5 | AI15: =SUM(AW10:AX21) -> 8534.27 | AK15: =AH15*AI15 -> 46938.485 | AM15: Pretratamiento (desarenado / desengrasado) | AQ15: 6.24 | AR15: 2.12 | AS15: 2.22 | AT15: 53.88 | AU15: 53.73 | AV15: 53.68 | AW15: 349.92 | AX15: 370.73 | AY15: 721.15 | AZ15: 721.15 | BA15: 51.52 | BB15: 48.24 | BC15: 42.94 | BD15: 38.99 | BE15: 51.84 | BF15: 47.4 | BG15: 43.18 | BH15: 38.96 | BI15: 260.4 | BJ15: 260.4 | BK15: 403.08 | BL15: 262.87 | BM15: 127.33 | BN15: 41.79 | BO15: 2.07 | BP15: 7.51 | BQ15: 6.74 | BR15: 4.66
AA16: ='Ambas EDAR'!K15 -> 10. -24 | AB16: ='Ambas EDAR'!N15 -> 727.77419 | AE16: E.T.7 | AF16: Caudalímetro electromagnético | AG16: 3 | AH16: - | AQ16: 7.24 | AR16: 0.87 | AS16: 1.59 | AT16: 53.12 | AU16: 53.26 | AV16: 53.67 | AW16: 371.35 | AX16: 370.21 | AY16: 747.42 | AZ16: 747.42 | BA16: 61.02 | BB16: 56.54 | BC16: 53.85 | BD16: 48.03 | BE16: 58.86 | BF16: 56.99 | BG16: 47.42 | BH16: 45.6 | BI16: 254.8 | BJ16: 254.8 | BK16: 403.08 | BL16: 256.52 | BM16: 108.74 | BN16: 188.85 | BO16: 2.45 | BP16: 6.77 | BQ16: 7.12 | BR16: 6.41
AA17: ='Ambas EDAR'!K16 -> 11. -24 | AB17: ='Ambas EDAR'!N16 -> 332.1 | AE17: E.T.8 | AF17: Caudalímetro ultrasónico | AG17: 2 | AH17: - | AQ17: 8.24 | AR17: 4.16 | AS17: 2.41 | AT17: 56.49 | AU17: 56.15 | AV17: 59.95 | AW17: 376.27 | AX17: 375.99 | AY17: 747.42 | AZ17: 747.42 | BA17: 66.56 | BB17: 65.62 | BC17: 56.3 | BD17: 51.59 | BE17: 66.79 | BF17: 62.07 | BG17: 61.25 | BH17: 51.18 | BI17: 260.05 | BJ17: 260.03 | BK17: 256.52 | BL17: 261.28 | BM17: 10.3 | BN17: 127.76 | BO17: 6.54 | BP17: 9.59 | BQ17: 9.94 | BR17: 8.68
AA18: ='Ambas EDAR'!K17 -> 12. -24 | AB18: ='Ambas EDAR'!N17 -> 375.25806 | AE18: E.T.9 | AF18: Agitador tanque anaerobio | AG18: 2 | AH18: 2.5 | AI18: =SUM(AY10:AZ21) -> 17446.1 | AK18: =AH18*AI18 -> 43615.25 | AM18: Tanque anaerobio | AQ18: 9.24 | AR18: 1.86 | AS18: 2.33 | AT18: 47.5 | AU18: 47.7 | AV18: 47.5 | AW18: 354.67 | AX18: 355.98 | AY18: 711.18 | AZ18: 711.18 | BA18: 47.06 | BB18: 44.04 | BC18: 39.14 | BD18: 35.48 | BE18: 49.32 | BF18: 45.37 | BG18: 41.6 | BH18: 37.82 | BI18: 261.5 | BJ18: 261.5 | BK18: 261.28 | BL18: 261.23 | BM18: 17.98 | BN18: 122.4 | BO18: 4.19 | BP18: 8.64 | BQ18: 9.06 | BR18: 7.49
AE19: E.T.10 | AF19: Distribuidor | AG19: 1 | AH19: 0.55 | AQ19: 10.24 | AR19: 1.01 | AS19: 1.16 | AT19: 103.53 | AU19: 103.32 | AV19: 100.08 | AW19: 373.49 | AX19: 370.92 | AY19: 744.94 | AZ19: 744.94 | BA19: 50.23 | BB19: 47.36 | BC19: 42.76 | BD19: 39.36 | BE19: 59.02 | BF19: 55.25 | BG19: 51.7 | BH19: 48.14 | BI19: 361 | BJ19: 271 | BK19: 253.42 | BL19: 253.42 | BM19: 56.32 | BN19: 13.41 | BO19: 2.13 | BP19: 8.3 | BQ19: 8.82 | BR19: 6.44 | BT19: Se recirculó mucho fango en octubre
AE20: E.T.11 | AF20: Rotores de aireación | AG20: 8 | AH20: 15 | AI20: =SUM(BA10:BH21) -> 3557.88 | AK20: =AH20*AI20 -> 53368.2 | AM20: Canal de aireación (oxidation ditch) | AQ20: 11.24 | AR20: 1.78 | AS20: 1.54 | AT20: 52.68 | AU20: 53 | AV20: 52.42 | AW20: 367.99 | AX20: 368.27 | AY20: 684.01 | AZ20: 684.01 | BA20: 39.46 | BB20: 37.02 | BC20: 33.13 | BD20: 29.44 | BE20: 40.93 | BF20: 37.59 | BG20: 34.41 | BH20: 31.2 | BI20: 190.33 | BJ20: 280.33 | BK20: 280.43 | BL20: 280.44 | BM20: 594.5 | BN20: 1.38 | BO20: 3.31 | BP20: 9.33 | BQ20: 9.76 | BR20: 7.94
AE21: E.T.12 | AF21: Acelerador de corriente | AG21: 4 | AH21: 0.9 | AI21: =SUM(BI10:BL21) -> 13651.45 | AK21: =AH21*AI21 -> 12286.305 | AM21: Canal de aireación (oxidation ditch) | AQ21: 12.24 | AR21: 0.99 | AS21: 1 | AT21: 42.25 | AU21: 41.83 | AV21: 41.58 | AW21: 366.98 | AX21: 443.58 | AY21: 728.1 | AZ21: 728.1 | BA21: 29.28 | BB21: 27.49 | BC21: 24.8 | BD21: 23.47 | BE21: 28.95 | BF21: 26.47 | BG21: 24.18 | BH21: 21.94 | BI21: 293.89 | BJ21: 292.88 | BK21: 291.42 | BL21: 418.77 | BM21: 478.22 | BN21: 7.7 | BO21: 1.68 | BP21: 4.95 | BQ21: 3.96 | BR21: 3.19
AE22: E.T.13 | AF22: Vertedero automático | AG22: 2 | AH22: 0.75 | AR22: =AE9 -> E.T.1 | AT22: =AE10 -> E.T.1 | AW22: =AE15 -> E.T.6 | AY22: =AE18 -> E.T.9 | BA22: =AE20 -> E.T.11 | BI22: =AE21 -> E.T.12 | BM22: =AE25 -> E.T.16 | BO22: =AE31 -> E.T.22 | BP22: =AE32 -> E.T.23 | BQ22: =AE34 -> E.T.25 | BR22: =AE35 -> E.T.26
AE23: E.T.14 | AF23: Puente rascador | AG23: 1 | AH23: 0.37 | AI23: =24*366*AG23 -> 8784 | AK23: =AH23*AI23 -> 3250.08 | AM23: Decantador
AE24: E.T.15 | AF24: Aireador | AG24: 1 | AH24: 7.5 | AI24: 0 | AK24: =AH24*AI24 -> 0 | AM24: Tanque de homogeneización | AZ24: VOY A TENER UNA ∆ ENTRE EL CONSUMO QUE YO CALCULE Y EL TOTAL (PEDIR EL TOTAL). VER QUE TENGA SENTIDO Y ESTIMAR A QUÉ SE DEBE
AE25: E.T.16 | AF25: Bombeo interno | AG25: 2 | AH25: 1.3 | AI25: =SUM(BM10:BN21) -> 4754.74 | AK25: =AH25*AI25 -> 6181.162 | AM25: Bombeo de interno
AE26: E.T.17 | AF26: Medidor de nivel | AG26: 3 | AH26: - | AR26: EDAR CERCEDA COBELANS - Consumos mensuales por equipo (kWh) | BE26: Consumo eléctrico mensual [kWh] | BN26: Diferencia entre el consumo mensual de los equipos listados y el total
AE27: E.T.18 | AF27: Medidor de O2 | AG27: 2 | AH27: - | AR27: =AF9 -> Bombas de fangos en exceso | AS27: =AF10 -> Bombas de recirculación de fangos | AT27: =AF15 -> Soplantes | AU27: =AF18 -> Agitador tanque anaerobio | AV27: =AF20 -> Rotores de aireación | AW27: =AF21 -> Acelerador de corriente | AX27: =AF25 -> Bombeo interno | AY27: =AF31 -> Bomba a predeshidratador | AZ27: =AF32 -> Predeshidratador | BA27: =AF34 -> Centrífuga | BB27: =AF35 -> Bomba fangos a silo | BE27: Suma equipos | BF27: Diario op. | BG27: Diferencia | BH27: % restante | BN27: Outliers | BO27: Desviación | BQ27: Observaciones
AE28: E.T.19 | AF28: ––– | AG28: – | AH28: – | AQ28: 1.24 | AR28: =SUM(AR10:AS10)*$AH$9 -> 13.13 | AS28: =SUM(AT10:AV10)*$AH$10 -> 689.967 | AT28: =SUM(AW10:AX10)*$AH$15 -> 4127.09 | AU28: =SUM(AY10:AZ10)*$AH$18 -> 3607.45 | AV28: =SUM(BA10:BH10)*$AH$20 -> 3856.95 | AW28: =SUM(BI10:BL10)*$AH$21 -> 1111.068 | AX28: =SUM(BM10:BN10)*$AH$25 -> 736.164 | AY28: =BO10*$AH$31 -> 75.3 | AZ28: =BP10*$AH$32 -> 27.5625 | BA28: =BQ10*$AH$34 -> 824.78 | BB28: =BR10*$AH$35 -> 140.52 | BC28: =$AH$39*24*31 -> 5133.6 | BD28: 1.24 | BE28: =SUM(AR28:BB28) -> 15209.981 | BF28: 18521 | BG28: =BF28-BE28 -> 3311.0185 | BH28: =BG28/BF28 -> 0.17877104 | BN28: =IF(BH28<$BN$41, IF(BH28>($BN$41-2*$BN$42), BH28, "-"), IF(BH28<($BN$41+2*$BN$42), BH28, "-")) -> 0.17877104
AE29: E.T.20 | AF29: Preparación de polielectrolito | AG29: 1 | AH29: 0.5 | AQ29: 2.24 | AR29: =SUM(AR11:AS11)*$AH$9 -> 7.358 | AS29: =SUM(AT11:AV11)*$AH$10 -> 765.762 | AT29: =SUM(AW11:AX11)*$AH$15 -> 3803.525 | AU29: =SUM(AY11:AZ11)*$AH$18 -> 3607.45 | AV29: =SUM(BA11:BH11)*$AH$20 -> 0 | AW29: =SUM(BI11:BL11)*$AH$21 -> 997.812 | AX29: =SUM(BM11:BN11)*$AH$25 -> 816.53 | AY29: =BO11*$AH$31 -> 42.3 | AZ29: =BP11*$AH$32 -> 17.2575 | BA29: =BQ11*$AH$34 -> 425.7 | BB29: =BR11*$AH$35 -> 89.64 | BC29: =$AH$39*24*29 -> 4802.4 | BD29: 2.24 | BE29: =SUM(AR29:BB29) -> 10573.334 | BF29: 18083 | BG29: =BF29-BE29 -> 7509.6655 | BH29: =BG29/BF29 -> 0.4152887 | BN29: =IF(BH29<$BN$41, IF(BH29>($BN$41-2*$BN$42), BH29, "-"), IF(BH29<($BN$41+2*$BN$42), BH29, "-")) -> - | BO29: 0 | BP29: Rotores | BQ29: Afluente muy poco biodegradable, y bajo NT a la entrada
AE30: E.T.21 | AF30: Bomba dosificadora | AG30: 2 | AH30: 0.55 | AQ30: 3.24 | AR30: =SUM(AR12:AS12)*$AH$9 -> 7.8 | AS30: =SUM(AT12:AV12)*$AH$10 -> 845.711 | AT30: =SUM(AW12:AX12)*$AH$15 -> 2241.195 | AU30: =SUM(AY12:AZ12)*$AH$18 -> 3705.25 | AV30: =SUM(BA12:BH12)*$AH$20 -> 3113.25 | AW30: =SUM(BI12:BL12)*$AH$21 -> 1049.616 | AX30: =SUM(BM12:BN12)*$AH$25 -> 559.221 | AY30: =BO12*$AH$31 -> 50.55 | AZ30: =BP12*$AH$32 -> 16.4775 | BA30: =BQ12*$AH$34 -> 481.58 | BB30: =BR12*$AH$35 -> 89.68 | BC30: =$AH$39*24*31 -> 5133.6 | BD30: 3.24 | BE30: =SUM(AR30:BB30) -> 12160.33 | BF30: 18137 | BG30: =BF30-BE30 -> 5976.6695 | BH30: =BG30/BF30 -> 0.32952911 | BN30: =IF(BH30<$BN$41, IF(BH30>($BN$41-2*$BN$42), BH30, "-"), IF(BH30<($BN$41+2*$BN$42), BH30, "-")) -> 0.32952911 | BO30: - | BP30: Soplantes, rotores | BQ30: Materia orgánica y nitrógeno muy bajos a la entrada
AE31: E.T.22 | AF31: Bomba a predeshidratador | AG31: 1 | AH31: 7.5 | AI31: =SUM(BO10:BO21) -> 53.67 | AK31: =AH31*AI31 -> 402.525 | AM31: Deshidratación | AQ31: 4.24 | AR31: =SUM(AR13:AS13)*$AH$9 -> 12.623 | AS31: =SUM(AT13:AV13)*$AH$10 -> 537.199 | AT31: =SUM(AW13:AX13)*$AH$15 -> 3958.515 | AU31: =SUM(AY13:AZ13)*$AH$18 -> 3601.25 | AV31: =SUM(BA13:BH13)*$AH$20 -> 3594.6 | AW31: =SUM(BI13:BL13)*$AH$21 -> 997.209 | AX31: =SUM(BM13:BN13)*$AH$25 -> 685.438 | AY31: =BO13*$AH$31 -> 66.6 | AZ31: =BP13*$AH$32 -> 22.215 | BA31: =BQ13*$AH$34 -> 664.84 | BB31: =BR13*$AH$35 -> 138.52 | BC31: =$AH$39*24*30 -> 4968 | BD31: 4.24 | BE31: =SUM(AR31:BB31) -> 14279.009 | BF31: 17601 | BG31: =BF31-BE31 -> 3321.991 | BH31: =BG31/BF31 -> 0.18873876 | BN31: =IF(BH31<$BN$41, IF(BH31>($BN$41-2*$BN$42), BH31, "-"), IF(BH31<($BN$41+2*$BN$42), BH31, "-")) -> 0.18873876
AE32: E.T.23 | AF32: Predeshidratador | AG32: 1 | AH32: 0.75 | AI32: =SUM(BP10:BP21) -> 166.44 | AK32: =AH32*AI32 -> 124.83 | AM32: Deshidratación | AQ32: 5.24 | AR32: =SUM(AR14:AS14)*$AH$9 -> 0.013 | AS32: =SUM(AT14:AV14)*$AH$10 -> 687.735 | AT32: =SUM(AW14:AX14)*$AH$15 -> 4118.235 | AU32: =SUM(AY14:AZ14)*$AH$18 -> 3672.75 | AV32: =SUM(BA14:BH14)*$AH$20 -> 5361.15 | AW32: =SUM(BI14:BL14)*$AH$21 -> 1014.597 | AX32: =SUM(BM14:BN14)*$AH$25 -> 918.125 | AY32: =BO14*$AH$31 -> 0 | AZ32: =BP14*$AH$32 -> 0 | BA32: =BQ14*$AH$34 -> 0 | BB32: =BR14*$AH$35 -> 0 | BC32: =$AH$39*24*31 -> 5133.6 | BD32: 5.24 | BE32: =SUM(AR32:BB32) -> 15772.605 | BF32: 24376 | BG32: =BF32-BE32 -> 8603.395 | BH32: =BG32/BF32 -> 0.35294532 | BN32: =IF(BH32<$BN$41, IF(BH32>($BN$41-2*$BN$42), BH32, "-"), IF(BH32<($BN$41+2*$BN$42), BH32, "-")) -> 0.35294532 | BO32: 0 | BP32: Deshidratación | BQ32: SST y materia orgánica bajos a la entrada
AE33: E.T.24 | AF33: Bomba fangos a centrífuga | AG33: 1 | AH33: 3 | AQ33: 6.24 | AR33: =SUM(AR15:AS15)*$AH$9 -> 5.642 | AS33: =SUM(AT15:AV15)*$AH$10 -> 499.999 | AT33: =SUM(AW15:AX15)*$AH$15 -> 3963.575 | AU33: =SUM(AY15:AZ15)*$AH$18 -> 3605.75 | AV33: =SUM(BA15:BH15)*$AH$20 -> 5446.05 | AW33: =SUM(BI15:BL15)*$AH$21 -> 1068.075 | AX33: =SUM(BM15:BN15)*$AH$25 -> 219.856 | AY33: =BO15*$AH$31 -> 15.525 | AZ33: =BP15*$AH$32 -> 5.6325 | BA33: =BQ15*$AH$34 -> 148.28 | BB33: =BR15*$AH$35 -> 18.64 | BC33: =$AH$39*24*30 -> 4968 | BD33: 6.24 | BE33: =SUM(AR33:BB33) -> 14997.024 | BF33: 18087 | BG33: =BF33-BE33 -> 3089.9755 | BH33: =BG33/BF33 -> 0.17083958 | BN33: =IF(BH33<$BN$41, IF(BH33>($BN$41-2*$BN$42), BH33, "-"), IF(BH33<($BN$41+2*$BN$42), BH33, "-")) -> 0.17083958
AE34: E.T.25 | AF34: Centrífuga | AG34: 1 | AH34: 22 | AI34: =SUM(BQ10:BQ21) -> 164.35 | AK34: =AH34*AI34 -> 3615.7 | AM34: Deshidratación | AQ34: 7.24 | AR34: =SUM(AR16:AS16)*$AH$9 -> 3.198 | AS34: =SUM(AT16:AV16)*$AH$10 -> 496.155 | AT34: =SUM(AW16:AX16)*$AH$15 -> 4078.58 | AU34: =SUM(AY16:AZ16)*$AH$18 -> 3737.1 | AV34: =SUM(BA16:BH16)*$AH$20 -> 6424.65 | AW34: =SUM(BI16:BL16)*$AH$21 -> 1052.28 | AX34: =SUM(BM16:BN16)*$AH$25 -> 386.867 | AY34: =BO16*$AH$31 -> 18.375 | AZ34: =BP16*$AH$32 -> 5.0775 | BA34: =BQ16*$AH$34 -> 156.64 | BB34: =BR16*$AH$35 -> 25.64 | BC34: =$AH$39*24*31 -> 5133.6 | BD34: 7.24 | BE34: =SUM(AR34:BB34) -> 16384.562 | BF34: 18241 | BG34: =BF34-BE34 -> 1856.4375 | BH34: =BG34/BF34 -> 0.10177279 | BN34: =IF(BH34<$BN$41, IF(BH34>($BN$41-2*$BN$42), BH34, "-"), IF(BH34<($BN$41+2*$BN$42), BH34, "-")) -> 0.10177279 | BO34: + | BP34: Rotores | BQ34: Alto NT y biodegradabilidad del afluente sobre el promedio
AE35: E.T.26 | AF35: Bomba fangos a silo | AG35: 1 | AH35: 4 | AI35: =SUM(BR10:BR21) -> 159.4 | AK35: =AH35*AI35 -> 637.6 | AM35: Deshidratación | AQ35: 8.24 | AR35: =SUM(AR17:AS17)*$AH$9 -> 8.541 | AS35: =SUM(AT17:AV17)*$AH$10 -> 535.029 | AT35: =SUM(AW17:AX17)*$AH$15 -> 4137.43 | AU35: =SUM(AY17:AZ17)*$AH$18 -> 3737.1 | AV35: =SUM(BA17:BH17)*$AH$20 -> 7220.4 | AW35: =SUM(BI17:BL17)*$AH$21 -> 934.092 | AX35: =SUM(BM17:BN17)*$AH$25 -> 179.478 | AY35: =BO17*$AH$31 -> 49.05 | AZ35: =BP17*$AH$32 -> 7.1925 | BA35: =BQ17*$AH$34 -> 218.68 | BB35: =BR17*$AH$35 -> 34.72 | BC35: =$AH$39*24*31 -> 5133.6 | BD35: 8.24 | BE35: =SUM(AR35:BB35) -> 17061.713 | BF35: 19265 | BG35: =BF35-BE35 -> 2203.2875 | BH35: =BG35/BF35 -> 0.11436738 | BN35: =IF(BH35<$BN$41, IF(BH35>($BN$41-2*$BN$42), BH35, "-"), IF(BH35<($BN$41+2*$BN$42), BH35, "-")) -> 0.11436738
AE36: E.T.27 | AF36: Bombas de agua de lavado | AG36: 3 | AH36: 3 | AQ36: 9.24 | AR36: =SUM(AR18:AS18)*$AH$9 -> 5.447 | AS36: =SUM(AT18:AV18)*$AH$10 -> 442.37 | AT36: =SUM(AW18:AX18)*$AH$15 -> 3908.575 | AU36: =SUM(AY18:AZ18)*$AH$18 -> 3555.9 | AV36: =SUM(BA18:BH18)*$AH$20 -> 5097.45 | AW36: =SUM(BI18:BL18)*$AH$21 -> 940.959 | AX36: =SUM(BM18:BN18)*$AH$25 -> 182.494 | AY36: =BO18*$AH$31 -> 31.425 | AZ36: =BP18*$AH$32 -> 6.48 | BA36: =BQ18*$AH$34 -> 199.32 | BB36: =BR18*$AH$35 -> 29.96 | BC36: =$AH$39*24*30 -> 4968 | BD36: 9.24 | BE36: =SUM(AR36:BB36) -> 14400.38 | BF36: 17577 | BG36: =BF36-BE36 -> 3176.62 | BH36: =BG36/BF36 -> 0.18072595 | BN36: =IF(BH36<$BN$41, IF(BH36>($BN$41-2*$BN$42), BH36, "-"), IF(BH36<($BN$41+2*$BN$42), BH36, "-")) -> 0.18072595
AE37: E.T.28 | AF37: Filtro autolimpiante | AG37: 1 | AH37: - | AQ37: 10.24 | AR37: =SUM(AR19:AS19)*$AH$9 -> 2.821 | AS37: =SUM(AT19:AV19)*$AH$10 -> 951.483 | AT37: =SUM(AW19:AX19)*$AH$15 -> 4094.255 | AU37: =SUM(AY19:AZ19)*$AH$18 -> 3724.7 | AV37: =SUM(BA19:BH19)*$AH$20 -> 5907.3 | AW37: =SUM(BI19:BL19)*$AH$21 -> 1024.956 | AX37: =SUM(BM19:BN19)*$AH$25 -> 90.649 | AY37: =BO19*$AH$31 -> 15.975 | AZ37: =BP19*$AH$32 -> 6.225 | BA37: =BQ19*$AH$34 -> 194.04 | BB37: =BR19*$AH$35 -> 25.76 | BC37: =$AH$39*24*31 -> 5133.6 | BD37: 10.24 | BE37: =SUM(AR37:BB37) -> 16038.164 | BF37: 18604 | BG37: =BF37-BE37 -> 2565.836 | BH37: =BG37/BF37 -> 0.13791851 | BN37: =IF(BH37<$BN$41, IF(BH37>($BN$41-2*$BN$42), BH37, "-"), IF(BH37<($BN$41+2*$BN$42), BH37, "-")) -> 0.13791851
AE38: E.T.29 | AF38: Compresor | AG38: 1 | AH38: 2.2 | AQ38: 11.24 | AR38: =SUM(AR20:AS20)*$AH$9 -> 4.316 | AS38: =SUM(AT20:AV20)*$AH$10 -> 490.11 | AT38: =SUM(AW20:AX20)*$AH$15 -> 4049.43 | AU38: =SUM(AY20:AZ20)*$AH$18 -> 3420.05 | AV38: =SUM(BA20:BH20)*$AH$20 -> 4247.7 | AW38: =SUM(BI20:BL20)*$AH$21 -> 928.377 | AX38: =SUM(BM20:BN20)*$AH$25 -> 774.644 | AY38: =BO20*$AH$31 -> 24.825 | AZ38: =BP20*$AH$32 -> 6.9975 | BA38: =BQ20*$AH$34 -> 214.72 | BB38: =BR20*$AH$35 -> 31.76 | BC38: =$AH$39*24*30 -> 4968 | BD38: 11.24 | BE38: =SUM(AR38:BB38) -> 14192.93 | BF38: 17680 | BG38: =BF38-BE38 -> 3487.0705 | BH38: =BG38/BF38 -> 0.19723249 | BN38: =IF(BH38<$BN$41, IF(BH38>($BN$41-2*$BN$42), BH38, "-"), IF(BH38<($BN$41+2*$BN$42), BH38, "-")) -> 0.19723249
AE39: E.T.30 | AF39: Desinfección UVC | AG39: 1 | AH39: 6.9 | AI39: =24*366*AG39 -> 8784 | AK39: =AH39*AI39 -> 60609.6 | AQ39: 12.24 | AR39: =SUM(AR21:AS21)*$AH$9 -> 2.587 | AS39: =SUM(AT21:AV21)*$AH$10 -> 389.546 | AT39: =SUM(AW21:AX21)*$AH$15 -> 4458.08 | AU39: =SUM(AY21:AZ21)*$AH$18 -> 3640.5 | AV39: =SUM(BA21:BH21)*$AH$20 -> 3098.7 | AW39: =SUM(BI21:BL21)*$AH$21 -> 1167.264 | AX39: =SUM(BM21:BN21)*$AH$25 -> 631.696 | AY39: =BO21*$AH$31 -> 12.6 | AZ39: =BP21*$AH$32 -> 3.7125 | BA39: =BQ21*$AH$34 -> 87.12 | BB39: =BR21*$AH$35 -> 12.76 | BC39: =$AH$39*24*31 -> 5133.6 | BD39: 12.24 | BE39: =SUM(AR39:BB39) -> 13504.566 | BF39: 15244 | BG39: =BF39-BE39 -> 1739.4345 | BH39: =BG39/BF39 -> 0.11410617 | BN39: =IF(BH39<$BN$41, IF(BH39>($BN$41-2*$BN$42), BH39, "-"), IF(BH39<($BN$41+2*$BN$42), BH39, "-")) -> 0.11410617
AE40: Total | AH40: =SUMPRODUCT(AG8:AG39, AH8:AH39) -> 239.54 | AI40: - | AK40: kWh anual | AL40: kWh diarios
AK41: =SUM(AK8:AL39) -> 238434.28 | AL41: =AK41/366 -> 651.45978 | AQ41: media | AR41: =AVERAGE(AR28:AR39) -> 6.123 | AS41: =AVERAGE(AS28:AS39) -> 610.92217 | AT41: =AVERAGE(AT28:AT39) -> 3911.5404 | AU41: =AVERAGE(AU28:AU39) -> 3634.6042 | AV41: =AVERAGE(AV28:AV39) -> 4447.35 | AW41: =AVERAGE(AW28:AW39) -> 1023.8587 | AX41: =AVERAGE(AX28:AX39) -> 515.09683 | AY41: =AVERAGE(AY28:AY39) -> 33.54375 | ... BB41: =AVERAGE(BB28:BB39) -> 53.133333 | BM41: Promedio | BN41: =AVERAGE(BH28:BH39) -> 0.20685298 | BP41: Los valores en amarillo se desviaron entre 1σ y 2σ, mientras que el valor en rojo se desvió más de 2σ
BM42: StDev | BN42: =STDEV(BH28:BH39) -> 0.10268047
...

Sheet Vedra tabla
R2: Valores límites
R3: Parámetros | T3: EDARI Cerceda - Cobelans | U3: EDAR VEDRA
R5: DBO5 | S5: (mg/L) | T5: 25 | U5: 25
R6: DQO | S6: (mg/L) | T6: 125 | U6: 125
R7: SST | S7: (mg/L) | T7: 35 | U7: 35
R8: NT | S8: (mg/L) | T8: 15 | U8: 15
R9: PT | S9: (mg/L) | T9: 2 | U9: 2
R10: pH | S10: (ud.pH) | T10: 5.5 - 9.5 | U10: 5.5 - 9.5
R11: Amoniaco | S11: (mg/L) | T11: 2 | U11: ---
R12: A y G | S12: (mg/L) | T12: --- | U12: 25
R13: Det. Anion. | S13: (mg/L) | T13: --- | U13: 3
R14: Coliformes totales | S14: (NMP/100ml) | T14: 500 | U14: 500
R15: Coliformes fecales | S15: (NMP/100ml) | T15: 100 | U15: 100
R16: Escherichia coli | S16: (NMP/100ml) | T16: 100 | U16: ---
B21: En la entrada de la EDAR de Vedra no te pongo las fechas porque se trata de muestreos durante la puesta en marcha, no se realizan muestreos rutinarios mensuales desde hace 2 años:
B22: CONCENTRACIONES DE ENTRADA DE LA EDAR VEDRA
B23: Parámetros | C23: Unidades | P23: MEDIA*
B24: DBO5 | C24: mg/L | D24: 499 | E24: 416 | F24: 316 | G24: 63 | H24: 66 | I24: 49 | J24: 111 | K24: 74 | L24: 44 | M24: 33 | N24: 872 | O24: 92 | P24: =AVERAGE(D24:O24) -> 219.58333
B25: DQO | C25: mg/L | D25: 1096 | E25: 900 | F25: 512 | G25: 190 | H25: 210 | I25: 98 | J25: 316 | K25: 188 | L25: 360 | M25: 60 | N25: 2840 | O25: 515 | P25: =AVERAGE(D25:O25) -> 607.08333
B26: SST | C26: mg/L | D26: 11 | E26: 127 | F26: 92 | G26: 44 | H26: 97 | I26: 23.8 | J26: 249.6 | K26: 58.4 | L26: 56.2 | M26: 30 | N26: 2064 | O26: 522 | P26: =AVERAGE(D26:O26) -> 281.25
B27: NT | C27: mg/L | D27: 172 | E27: 77 | F27: 78 | G27: 37 | H27: 56 | I27: 28.6 | J27: 33.4 | K27: 28.8 | L27: 47.5 | M27: 15.5 | N27: 45.5 | O27: 53.6 | P27: =AVERAGE(D27:O27) -> 56.075
B28: PT | C28: mg/L | D28: 110 | E28: 9.2 | F28: 7.8 | G28: 57 | H28: 8.3 | I28: 3.1 | J28: 7.6 | K28: 2.6 | L28: 4.4 | M28: 0.9 | N28: 269 | O28: 11 | P28: =AVERAGE(D28:O28) -> 40.908333
B29: DBO5 / DQO | C29: [ - ] | D29: =D24/D25 -> 0.45529197 | E29: =E24/E25 -> 0.46222222 | F29: =F24/F25 -> 0.6171875 | G29: =G24/G25 -> 0.33157895 | H29: =H24/H25 -> 0.31428571 | I29: =I24/I25 -> 0.5 | J29: =J24/J25 -> 0.35126582 | K29: =K24/K25 -> 0.39361702 | ... O29: =O24/O25 -> 0.17864078 | P29: =AVERAGE(D29:O29) -> 0.3819462
B30: SST * 1.42 | C30: mg/L | D30: =D26*1.42 -> 15.62 | E30: =E26*1.42 -> 180.34 | F30: =F26*1.42 -> 130.64 | G30: =G26*1.42 -> 62.48 | H30: =H26*1.42 -> 137.74 | I30: =I26*1.42 -> 33.796 | J30: =J26*1.42 -> 354.432 | K30: =K26*1.42 -> 82.928 | ... O30: =O26*1.42 -> 741.24 | P30: =AVERAGE(D30:O30) -> 399.375
B31: SST / DQO | C31: [ - ] | D31: =D26/D25 -> 0.010036496 | E31: =E26/E25 -> 0.14111111 | F31: =F26/F25 -> 0.1796875 | G31: =G26/G25 -> 0.23157895 | H31: =H26/H25 -> 0.46190476 | I31: =I26/I25 -> 0.24285714 | J31: =J26/J25 -> 0.78987342 | K31: =K26/K25 -> 0.3106383 | ... O31: =O26/O25 -> 1.0135922 | P31: =AVERAGE(D31:O31) -> 0.39701263
B32: SST / DBO5 | C32: [ - ] | D32: =D26/D24 -> 0.022044088 | E32: =E26/E24 -> 0.30528846 | F32: =F26/F24 -> 0.29113924 | G32: =G26/G24 -> 0.6984127 | H32: =H26/H24 -> 1.469697 | I32: =I26/I24 -> 0.48571429 | J32: =J26/J24 -> 2.2486486 | K32: =K26/K24 -> 0.78918919 | ... O32: =O26/O24 -> 5.673913 | P32: =AVERAGE(D32:O32) -> 1.3781152
D34: *Para la media solo considero los datos del periodo 1 al 9 y luego el 12, pues los del 11 son demasiado diferentes, y en el 10 no hay datos de la salida.
B37: CONCENTRACIONES DE SALIDA DE LA EDAR DE VEDRA
B38: Parámetros | C38: Unidades | D38: 1.24 | E38: 2.24 | F38: 3.24 | G38: 4.24 | H38: 5.24 | I38: 6.24 | J38: 7.24 | K38: 8.24 | L38: 9.24 | M38: 10.24 | N38: 11.24 | O38: 12.24 | P38: MEDIA
B39: DBO5 | C39: mg/L | D39: 18 | E39: 22 | F39: 21 | G39: 22 | H39: 20 | I39: 63 | J39: 6 | K39: 6 | L39: 13 | M39: --- | N39: 5 | O39: 25 | P39: =AVERAGE(D39:O39) -> 20.090909
B40: DQO | C40: mg/L | D40: 51 | E40: 70 | F40: 48 | G40: 50 | H40: 58 | I40: 126 | J40: 12 | K40: 34 | L40: 43 | M40: --- | N40: 30 | O40: 41 | P40: =AVERAGE(D40:O40) -> 51.181818
B41: SST | C41: mg/L | D41: 22 | E41: 28.4 | F41: 34.2 | G41: 15 | H41: 13.2 | I41: 16.7 | J41: 2 | K41: 2.7 | L41: 21.2 | M41: --- | N41: 14 | O41: 5 | P41: =AVERAGE(D41:O41) -> 15.854545
B42: NT | C42: mg/L | D42: 13.3 | E42: 14.5 | F42: 6.6 | G42: 14.1 | H42: 14 | I42: 27.8 | J42: 3.7 | K42: 4.9 | L42: 10.3 | M42: --- | N42: 9.4 | O42: 9 | P42: =AVERAGE(D42:O42) -> 11.6
B43: PT | C43: mg/L | D43: 0.5 | E43: 0.7 | F43: 0.6 | G43: 0.6 | H43: 0.8 | I43: 5.6 | J43: 1.2 | K43: 1.7 | L43: 0.7 | M43: --- | N43: 1.35 | O43: 1.56 | P43: =AVERAGE(D43:O43) -> 1.3918182
B44: A y G | C44: mg/L | D44: 5 | E44: 5 | F44: 5 | G44: 6.4 | H44: 5 | I44: --- | J44: 5 | K44: 5 | L44: 5 | M44: --- | N44: 0.5 | O44: 0.5 | P44: =AVERAGE(D44:O44) -> 4.24
B45: Det. Anion. | C45: mg/L | D45: 0.6 | E45: 0.4 | F45: 0.3 | G45: 0.3 | H45: 0.9 | I45: --- | J45: 0.4 | K45: 0.5 | L45: 0.2 | M45: --- | N45: 0.2 | O45: 0.2 | P45: =AVERAGE(D45:O45) -> 0.4
B46: DBO5 / DQO | C46: [ - ] | D46: =D39/D40 -> 0.35294118 | E46: =E39/E40 -> 0.31428571 | F46: =F39/F40 -> 0.4375 | G46: =G39/G40 -> 0.44 | H46: =H39/H40 -> 0.34482759 | I46: =I39/I40 -> 0.5 | J46: =J39/J40 -> 0.5 | K46: =K39/K40 -> 0.17647059 | L46: =L39/L40 -> 0.30232558 | M46: --- | N46: =N39/N40 -> 0.16666667 | O46: =O39/O40 -> 0.6097561 | P46: =AVERAGE(D46:O46) -> 0.37679758
B47: SST * 1.42 | C47: mg/L | D47: =D41*1.42 -> 31.24 | E47: =E41*1.42 -> 40.328 | F47: =F41*1.42 -> 48.564 | G47: =G41*1.42 -> 21.3 | H47: =H41*1.42 -> 18.744 | I47: =I41*1.42 -> 23.714 | J47: =J41*1.42 -> 2.84 | K47: =K41*1.42 -> 3.834 | L47: =L41*1.42 -> 30.104 | M47: --- | N47: =N41*1.42 -> 19.88 | O47: =O41*1.42 -> 7.1 | P47: =AVERAGE(D47:O47) -> 22.513455
B48: SST / DQO | C48: [ - ] | D48: =D41/D40 -> 0.43137255 | E48: =E41/E40 -> 0.40571429 | F48: =F41/F40 -> 0.7125 | G48: =G41/G40 -> 0.3 | H48: =H41/H40 -> 0.22758621 | I48: =I41/I40 -> 0.13253968 | J48: =J41/J40 -> 0.16666667 | K48: =K41/K40 -> 0.079411765 | L48: =L41/L40 -> 0.49302326 | M48: --- | N48: =N41/N40 -> 0.46666667 | O48: =O41/O40 -> 0.12195122 | P48: =AVERAGE(D48:O48) -> 0.32158475
B49: SST / DBO5 | C49: [ - ] | D49: =D41/D39 -> 1.2222222 | E49: =E41/E39 -> 1.2909091 | F49: =F41/F39 -> 1.6285714 | G49: =G41/G39 -> 0.68181818 | H49: =H41/H39 -> 0.66 | I49: =I41/I39 -> 0.26507937 | J49: =J41/J39 -> 0.33333333 | K49: =K41/K39 -> 0.45 | L49: =L41/L39 -> 1.6307692 | M49: --- | N49: =N41/N39 -> 2.8 | O49: =O41/O39 -> 0.2 | P49: =AVERAGE(D49:O49) -> 1.0147912
...

Sheet Vedra Balance
R2: ='Vedra tabla'!Q70 -> Caudales mensuales en m3 | S2: ='Vedra tabla'!R70 -> 0 | T2: ='Vedra tabla'!S70 -> 0
R3: ='Vedra tabla'!Q71 -> Mes | S3: ='Vedra tabla'!R71 -> EDAR VEDRA | T3: ='Vedra tabla'!S71 -> 0 | AA3: Consumos eléctricos
R4: ='Vedra tabla'!Q72 -> 0 | S4: ='Vedra tabla'!R72 -> 0 | T4: ='Vedra tabla'!S72 -> 0 | AA4: Equipo | AC4: Cantidad | AD4: Potencia [kW] | AE4: t de operación [h/año] | AG4: Consumo anual [kWh]
R5: ='Vedra tabla'!Q73 -> 1. -24 | S5: ='Vedra tabla'!R73 -> 652 | T5: ='Vedra tabla'!S73 -> 0 | AA5: E.T.1 | AB5: Tornillo | AC5: 1 | AD5: 0.75 | AE5: =SUM(AB19:AB30) -> 151 | AG5: =AD5*AE5 -> 113.25
R6: ='Vedra tabla'!Q74 -> 2. -24 | S6: ='Vedra tabla'!R74 -> 641 | T6: ='Vedra tabla'!S74 -> 0 | AA6: E.T.2 | AB6: Bomba sumergible 1 | AC6: 2 | AD6: 1.9 | AE6: =SUM(AC19:AD30) -> 3158 | AG6: =AD6*AE6 -> 6000.2
R7: ='Vedra tabla'!Q75 -> 3. -24 | S7: ='Vedra tabla'!R75 -> 846 | T7: ='Vedra tabla'!S75 -> 0 | AA7: E.T.3 | AB7: Agitador | AC7: 1 | AD7: 0.79 | AE7: =SUM(AE19:AE30) -> 3500 | AG7: =AD7*AE7 -> 2765
R8: ='Vedra tabla'!Q76 -> 4. -24 | S8: ='Vedra tabla'!R76 -> 451 | T8: ='Vedra tabla'!S76 -> 0 | AA8: E.T.4 | AB8: – | AC8: – | AD8: – | AE8: - | AG8: -
R9: ='Vedra tabla'!Q77 -> 5. -24 | S9: ='Vedra tabla'!R77 -> 515 | T9: ='Vedra tabla'!S77 -> 0 | AA9: E.T.5 | AB9: Planta compacta | AC9: 1 | AD9: 5.65 | AE9: =365*24 -> 8760 | AG9: =AD9*AE9 -> 49494
R10: ='Vedra tabla'!Q78 -> 6. -24 | S10: ='Vedra tabla'!R78 -> 376 | T10: ='Vedra tabla'!S78 -> 0 | AA10: E.T.6 | AB10: Equipo UV | AC10: 1 | AD10: 1.2 | AE10: =SUM(AH19:AH30) -> 3158 | AG10: =AD10*AE10 -> 3789.6
R11: ='Vedra tabla'!Q79 -> 7. -24 | S11: ='Vedra tabla'!R79 -> 299 | T11: ='Vedra tabla'!S79 -> 0 | AA11: E.T.7 | AB11: DMR HR1A-013/150/E0.25/A | AC11: 1 | AD11: 0.25
R12: ='Vedra tabla'!Q80 -> 8. -24 | S12: ='Vedra tabla'!R80 -> 198 | T12: ='Vedra tabla'!S80 -> 0 | AA12: E.T.8 | AB12: Bombas de PAC y metanol | AC12: 2 | AD12: 0.05 | AE12: =SUM(AF19:AG30) -> 16522 | AG12: =AD12*AE12 -> 826.1
R13: ='Vedra tabla'!Q81 -> 9. -24 | S13: ='Vedra tabla'!R81 -> --- | T13: ='Vedra tabla'!S81 -> 0 | V13: No se consideran los periodos 9, 10 ni 11 por falta de datos
R14: ='Vedra tabla'!Q82 -> 10. -24 | S14: ='Vedra tabla'!R82 -> --- | T14: ='Vedra tabla'!S82 -> 0 | AA14: Total | AD14: =SUMPRODUCT(AC5:AC12,AD5:AD12) -> 12.54 | AE14: - | AG14: =SUM(AG5:AH12) -> 62988.15
R15: ='Vedra tabla'!Q83 -> 11. -24 | S15: ='Vedra tabla'!R83 -> 485 | T15: ='Vedra tabla'!S83 -> 0
R16: ='Vedra tabla'!Q84 -> 12. -24 | S16: ='Vedra tabla'!R84 -> 523 | T16: ='Vedra tabla'!S84 -> 0
AB17: EDAR VEDRA - HORAS DE EQUIPOS (horas/mes) | AK17: EDAR VEDRA - CONSUMOS MENSUALES DE EQUIPOS (kWh) | AR17: Consumo eléctrico mensual [kWh]
AB18: TORNILLO | AC18: BOMBA 1 | AD18: BOMBA 2 | AE18: AGITADOR | AF18: BOMBA PAC | AG18: BOMBA METANOL | AH18: RAYOS UV | AK18: TORNILLO | AL18: BOMBAS SUMERGIBLES | AM18: AGITADOR | AN18: BOMBAS PAC Y METANOL | AO18: RAYOS UV | AR18: Suma equipos | AS18: Diario op. | AT18: Diferencia | AU18: % restante
AA19: 1.24 | AB19: 2 | AC19: 148 | AD19: 245 | AE19: 407 | AF19: 838 | AG19: 838 | AH19: 393 | AJ19: 1.24 | AK19: =AB19*$AD$5 -> 1.5 | AL19: =SUM(AC19:AD19)*$AD$6 -> 746.7 | AM19: =AE19*$AD$7 -> 321.53 | AN19: =SUM(AF19:AG19)*$AD$12 -> 83.8 | AO19: =AH19*$AD$10 -> 471.6 | AQ19: 1.24 | AR19: =SUM(AK19:AO19) -> 1625.13 | AT19: =IF(ISBLANK(AS19), "", AS19-AR19) | AU19: =IF(ISBLANK(AS19), "",AT19/AS19)
AA20: 2.24 | AB20: 2 | AC20: 122 | AD20: 191 | AE20: 330 | AF20: 685 | AG20: 685 | AH20: 313 | AJ20: 2.24 | AK20: =AB20*$AD$5 -> 1.5 | AL20: =SUM(AC20:AD20)*$AD$6 -> 594.7 | AM20: =AE20*$AD$7 -> 260.7 | AN20: =SUM(AF20:AG20)*$AD$12 -> 68.5 | AO20: =AH20*$AD$10 -> 375.6 | AQ20: 2.24 | AR20: =SUM(AK20:AO20) -> 1301 | AT20: =IF(ISBLANK(AS20), "", AS20-AR20) | AU20: =IF(ISBLANK(AS20), "",AT20/AS20)
B21: ='Vedra tabla'!Q55 -> Concentraciones de la EDAR de Vedra | C21: ='Vedra tabla'!R55 -> 0 | D21: ='Vedra tabla'!S55 -> 0 | E21: ='Vedra tabla'!T55 -> 0 | F21: ='Vedra tabla'!U55 -> 0 | G21: ='Vedra tabla'!V55 -> 0 | I21: ='Vedra tabla'!S106 -> Cargas en la EDAR de Vedra | P21: Residuos removidos | AA21: 3.24 | AB21: 2 | AC21: 203 | AD21: 246 | AE21: 490 | AF21: 674 | AG21: 674 | AH21: 449 | AJ21: 3.24 | AK21: =AB21*$AD$5 -> 1.5 | AL21: =SUM(AC21:AD21)*$AD$6 -> 853.1 | AM21: =AE21*$AD$7 -> 387.1 | AN21: =SUM(AF21:AG21)*$AD$12 -> 67.4 | AO21: =AH21*$AD$10 -> 538.8 | AQ21: 3.24 | AR21: =SUM(AK21:AO21) -> 1847.9 | AT21: =IF(ISBLANK(AS21), "", AS21-AR21) | AU21: =IF(ISBLANK(AS21), "",AT21/AS21)
B22: ='Vedra tabla'!Q56 -> Parámetros | C22: ='Vedra tabla'!R56 -> Unidades | D22: ='Vedra tabla'!S56 -> Media IN | E22: ='Vedra tabla'!T56 -> Media OUT | F22: ='Vedra tabla'!U56 -> Diferencia | G22: ='Vedra tabla'!V56 -> % eliminación | I22: ='Vedra tabla'!S107 -> Parámetros | J22: ='Vedra tabla'!T107 -> Unidades | K22: ='Vedra tabla'!U107 -> Media IN | L22: ='Vedra tabla'!V107 -> Media OUT | M22: ='Vedra tabla'!W107 -> Diferencia | N22: ='Vedra tabla'!X107 -> % eliminación | P22: Residuo | Q22: Cantidad | R22: Unidad | AA22: 4.24 | AB22: 2 | AC22: 82 | AD22: 188 | AE22: 279 | AF22: 784 | AG22: 776 | AH22: 270 | AJ22: 4.24 | AK22: =AB22*$AD$5 -> 1.5 | AL22: =SUM(AC22:AD22)*$AD$6 -> 513 | AM22: =AE22*$AD$7 -> 220.41 | AN22: =SUM(AF22:AG22)*$AD$12 -> 78 | AO22: =AH22*$AD$10 -> 324 | AQ22: 4.24 | AR22: =SUM(AK22:AO22) -> 1136.91 | AT22: =IF(ISBLANK(AS22), "", AS22-AR22) | AU22: =IF(ISBLANK(AS22), "",AT22/AS22)
B23: ='Vedra tabla'!Q57 -> DBO5 | C23: ='Vedra tabla'!R57 -> mg/L | D23: ='Vedra tabla'!S57 -> 187.33333 | E23: ='Vedra tabla'!T57 -> 22.555556 | F23: ='Vedra tabla'!U57 -> 164.77778 | G23: ='Vedra tabla'!V57 -> 0.87959668 | I23: ='Vedra tabla'!S108 -> DBO5 | J23: ='Vedra tabla'!T108 -> kg/d | K23: ='Vedra tabla'!U108 -> 3.7852161 | L23: ='Vedra tabla'!V108 -> 0.3787236 | M23: ='Vedra tabla'!W108 -> 3.4064925 | N23: ='Vedra tabla'!X108 -> 0.89994664 | P23: Lodos | Q23: 30 | R23: ton/año | AA23: 5.24 | AB23: 2 | AC23: 90 | AD23: 172 | AE23: 276 | AF23: 694 | AG23: 695 | AH23: 262 | AJ23: 5.24 | AK23: =AB23*$AD$5 -> 1.5 | AL23: =SUM(AC23:AD23)*$AD$6 -> 497.8 | AM23: =AE23*$AD$7 -> 218.04 | AN23: =SUM(AF23:AG23)*$AD$12 -> 69.45 | AO23: =AH23*$AD$10 -> 314.4 | AQ23: 5.24 | AR23: =SUM(AK23:AO23) -> 1101.19 | AT23: =IF(ISBLANK(AS23), "", AS23-AR23) | AU23: =IF(ISBLANK(AS23), "",AT23/AS23)
B24: ='Vedra tabla'!Q58 -> DQO | C24: ='Vedra tabla'!R58 -> mg/L | D24: ='Vedra tabla'!S58 -> 447.22222 | E24: ='Vedra tabla'!T58 -> 54.444444 | F24: ='Vedra tabla'!U58 -> 392.77778 | G24: ='Vedra tabla'!V58 -> 0.87826087 | I24: ='Vedra tabla'!S109 -> DQO | J24: ='Vedra tabla'!T109 -> kg/d | K24: ='Vedra tabla'!U109 -> 8.6030674 | L24: ='Vedra tabla'!V109 -> 0.91653889 | M24: ='Vedra tabla'!W109 -> 7.6865285 | N24: ='Vedra tabla'!X109 -> 0.89346371 | P24: Lodos | Q24: =Q23*1000/365 -> 82.191781 | R24: kg/d | S24: *Es solo para estimar la generación de lodos para los cálculos, pero en realidad los lodos se retiran una vez al año | AA24: 6.24 | AB24: 2 | AC24: 59 | AD24: 119 | AE24: 202 | AF24: 693 | AG24: 702 | AH24: 178 | AJ24: 6.24 | AK24: =AB24*$AD$5 -> 1.5 | AL24: =SUM(AC24:AD24)*$AD$6 -> 338.2 | AM24: =AE24*$AD$7 -> 159.58 | AN24: =SUM(AF24:AG24)*$AD$12 -> 69.75 | AO24: =AH24*$AD$10 -> 213.6 | AQ24: 6.24 | AR24: =SUM(AK24:AO24) -> 782.63 | AT24: =IF(ISBLANK(AS24), "", AS24-AR24) | AU24: =IF(ISBLANK(AS24), "",AT24/AS24)
B25: ='Vedra tabla'!Q59 -> SST | C25: ='Vedra tabla'!R59 -> mg/L | D25: ='Vedra tabla'!S59 -> 136.08889 | E25: ='Vedra tabla'!T59 -> 15.466667 | F25: ='Vedra tabla'!U59 -> 120.62222 | G25: ='Vedra tabla'!V59 -> 0.88634879 | I25: ='Vedra tabla'!S110 -> SST | J25: ='Vedra tabla'!T110 -> kg/d | K25: ='Vedra tabla'!U110 -> 2.189722 | L25: ='Vedra tabla'!V110 -> 0.31097377 | M25: ='Vedra tabla'!W110 -> 1.8787482 | N25: ='Vedra tabla'!X110 -> 0.85798482 | AA25: 7.24 | AB25: 3 | AC25: 53 | AD25: 92 | AE25: 208 | AF25: 561 | AG25: 838 | AH25: 145 | AJ25: 7.24 | AK25: =AB25*$AD$5 -> 2.25 | AL25: =SUM(AC25:AD25)*$AD$6 -> 275.5 | AM25: =AE25*$AD$7 -> 164.32 | AN25: =SUM(AF25:AG25)*$AD$12 -> 69.95 | AO25: =AH25*$AD$10 -> 174 | AQ25: 7.24 | AR25: =SUM(AK25:AO25) -> 686.02 | AT25: =IF(ISBLANK(AS25), "", AS25-AR25) | AU25: =IF(ISBLANK(AS25), "",AT25/AS25)
B26: ='Vedra tabla'!Q60 -> NT | C26: ='Vedra tabla'!R60 -> mg/L | D26: ='Vedra tabla'!S60 -> 62.711111 | E26: ='Vedra tabla'!T60 -> 11.988889 | F26: ='Vedra tabla'!U60 -> 50.722222 | G26: ='Vedra tabla'!V60 -> 0.80882353 | I26: ='Vedra tabla'!S111 -> NT | J26: ='Vedra tabla'!T111 -> kg/d | K26: ='Vedra tabla'!U111 -> 1.1892832 | L26: ='Vedra tabla'!V111 -> 0.19912723 | M26: ='Vedra tabla'!W111 -> 0.99015599 | N26: ='Vedra tabla'!X111 -> 0.83256534 | AA26: 8.24 | AB26: 127 | AC26: 32 | AD26: 61 | AE26: 105 | AF26: 94 | AG26: 734 | AH26: 93 | AJ26: 8.24 | AK26: =AB26*$AD$5 -> 95.25 | AL26: =SUM(AC26:AD26)*$AD$6 -> 176.7 | AM26: =AE26*$AD$7 -> 82.95 | AN26: =SUM(AF26:AG26)*$AD$12 -> 41.4 | AO26: =AH26*$AD$10 -> 111.6 | AQ26: 8.24 | AR26: =SUM(AK26:AO26) -> 507.9 | AT26: =IF(ISBLANK(AS26), "", AS26-AR26) | AU26: =IF(ISBLANK(AS26), "",AT26/AS26)
B27: ='Vedra tabla'!Q61 -> PT | C27: ='Vedra tabla'!R61 -> mg/L | D27: ='Vedra tabla'!S61 -> 24.066667 | E27: ='Vedra tabla'!T61 -> 1.4733333 | F27: ='Vedra tabla'!U61 -> 22.593333 | G27: ='Vedra tabla'!V61 -> 0.93878116 | I27: ='Vedra tabla'!S112 -> PT | J27: ='Vedra tabla'!T112 -> kg/d | K27: ='Vedra tabla'!U112 -> 0.44876615 | L27: ='Vedra tabla'!V112 -> 0.020401188 | M27: ='Vedra tabla'!W112 -> 0.42836497 | N27: ='Vedra tabla'!X112 -> 0.95453938 | AA27: 9.24 | AB27: 4 | AC27: 76 | AD27: 129 | AE27: 273 | AF27: 297 | AG27: 900 | AH27: 205 | AJ27: 9.24 | AK27: =AB27*$AD$5 -> 3 | AL27: =SUM(AC27:AD27)*$AD$6 -> 389.5 | AM27: =AE27*$AD$7 -> 215.67 | AN27: =SUM(AF27:AG27)*$AD$12 -> 59.85 | AO27: =AH27*$AD$10 -> 246 | AQ27: 9.24 | AR27: =SUM(AK27:AO27) -> 914.02 | AT27: =IF(ISBLANK(AS27), "", AS27-AR27) | AU27: =IF(ISBLANK(AS27), "",AT27/AS27)
B28: ='Vedra tabla'!Q62 -> A y G | C28: ='Vedra tabla'!R62 -> mg/L | D28: ='Vedra tabla'!S62 -> – | E28: ='Vedra tabla'!T62 -> 4.6125 | F28: ='Vedra tabla'!U62 -> – | G28: ='Vedra tabla'!V62 -> – | I28: ='Vedra tabla'!S113 -> A y G | J28: ='Vedra tabla'!T113 -> kg/d | K28: ='Vedra tabla'!U113 -> – | L28: ='Vedra tabla'!V113 -> 0.077500596 | M28: ='Vedra tabla'!W113 -> – | N28: ='Vedra tabla'!X113 -> – | AA28: 10.24 | AB28: 2 | AC28: 116 | AD28: 215 | AE28: 350 | AF28: 671 | AG28: 710 | AH28: 331 | AJ28: 10.24 | AK28: =AB28*$AD$5 -> 1.5 | AL28: =SUM(AC28:AD28)*$AD$6 -> 628.9 | AM28: =AE28*$AD$7 -> 276.5 | AN28: =SUM(AF28:AG28)*$AD$12 -> 69.05 | AO28: =AH28*$AD$10 -> 397.2 | AQ28: 10.24 | AR28: =SUM(AK28:AO28) -> 1373.15 | AT28: =IF(ISBLANK(AS28), "", AS28-AR28) | AU28: =IF(ISBLANK(AS28), "",AT28/AS28)
B29: ='Vedra tabla'!Q63 -> Det. Anion. | C29: ='Vedra tabla'!R63 -> mg/L | D29: ='Vedra tabla'!S63 -> – | E29: ='Vedra tabla'!T63 -> 0.45 | F29: ='Vedra tabla'!U63 -> – | G29: ='Vedra tabla'!V63 -> – | I29: ='Vedra tabla'!S114 -> Det. Anion. | J29: ='Vedra tabla'!T114 -> kg/d | K29: ='Vedra tabla'!U114 -> – | L29: ='Vedra tabla'!V114 -> 0.0074419063 | M29: ='Vedra tabla'!W114 -> – | N29: ='Vedra tabla'!X114 -> – | AA29: 11.24 | AB29: 2 | AC29: 66 | AD29: 160 | AE29: 286 | AF29: 773 | AG29: 819 | AH29: 226 | AJ29: 11.24 | AK29: =AB29*$AD$5 -> 1.5 | AL29: =SUM(AC29:AD29)*$AD$6 -> 429.4 | AM29: =AE29*$AD$7 -> 225.94 | AN29: =SUM(AF29:AG29)*$AD$12 -> 79.6 | AO29: =AH29*$AD$10 -> 271.2 | AQ29: 11.24 | AR29: =SUM(AK29:AO29) -> 1007.64 | AT29: =IF(ISBLANK(AS29), "", AS29-AR29) | AU29: =IF(ISBLANK(AS29), "",AT29/AS29)
B30: ='Vedra tabla'!Q64 -> Caudal | C30: ='Vedra tabla'!R64 -> m3/d | D30: ='Vedra tabla'!S64 -> 16.389869 | E30: ='Vedra tabla'!T64 -> 16.389869 | F30: ='Vedra tabla'!U64 -> – | G30: ='Vedra tabla'!V64 -> – | I30: ='Vedra tabla'!S115 -> Caudal | J30: ='Vedra tabla'!T115 -> m3/d | K30: ='Vedra tabla'!U115 -> 16.389869 | L30: ='Vedra tabla'!V115 -> 16.389869 | M30: ='Vedra tabla'!W115 -> – | N30: ='Vedra tabla'!X115 -> – | AA30: 12.24 | AB30: 1 | AC30: 76 | AD30: 217 | AE30: 294 | AF30: 674 | AG30: 713 | AH30: 293 | AJ30: 12.24 | AK30: =AB30*$AD$5 -> 0.75 | AL30: =SUM(AC30:AD30)*$AD$6 -> 556.7 | AM30: =AE30*$AD$7 -> 232.26 | AN30: =SUM(AF30:AG30)*$AD$12 -> 69.35 | AO30: =AH30*$AD$10 -> 351.6 | AQ30: 12.24 | AR30: =SUM(AK30:AO30) -> 1210.66 | AT30: =IF(ISBLANK(AS30), "", AS30-AR30) | AU30: =IF(ISBLANK(AS30), "",AT30/AS30)
AB31: =AA5 -> E.T.1 | AC31: =AA6 -> E.T.2 | AD31: =AA6 -> E.T.2 | AE31: =AA7 -> E.T.3 | AF31: =AA12 -> E.T.8 | AG31: =AA12 -> E.T.8 | AH31: =AA10 -> E.T.6 | AK31: =AA5 -> E.T.1 | AL31: =AA6 -> E.T.2 | AM31: =AA7 -> E.T.3 | AN31: =AA12 -> E.T.8 | AO31: =AA10 -> E.T.6
B33: Balance de masa equipo a equipo | Y33: Transporte de reactivos
AA34: en vedra se piden 12 garrafas de metanol cada 20 días aproximadamente y 8 garrafas cada 4 meses
AA35: Reactivos
AA36: Producto | AB36: Valor | AC36: Unidad
Y37: Magnasol | Z37: <––––> | AA37: PAC | AB37: =1 * 25 / 30 -> 0.83333333 | AC37: L/d | AD37: 1 garrafa de 25 L c/u al mes | AG37: Uso de reactivos
AA38: Metanol | AB38: =12 * 25 / 30 -> 10 | AC38: L/d | AD38: 12 garrafas de 25 L c/u al mes
D39: F12 | I39: F14 | J39: F15 | M39: F16
B40: F1 | C40: Pozo Imhoff | E40: F2 | F40: Pozo bombeo y homogeneización | H40: F3 | I40: Anóxico | K40: F4 | L40: Aireación extendida | N40: F5 | O40: Decantación | Q40: F6 | R40: Biofiltros | T40: F7 | U40: Desinfección UV | W40: F8
AA41: ρ PAC | AB41: 0.831 | AC41: kg/L | AD41: https://aniq.org.mx/pqta/pdf/Magnasol_4725(MSDS).pdf
C42: F11 | D42: F10 | I42: F13 | J42: F9 | O42: F9 | P42: F10 | S42: F17 | AA42: ρ metanol | AB42: 0.792 | AC42: kg/L | AD42: https://www.abpcoatings.com/wp-content/uploads/2019/02/Metanol.pdf
...

Sheet Entradas y salidas globales
B2: Entradas y salidas globales de ambas EDAR
B11: Entradas en la EDARI de Cerceda (anual) | I11: Entradas en la EDAR de Vedra (anual)
B12: Item | C12: Cantidad | D12: Unidad | I12: Item | J12: Cantidad | K12: Unidad
B13: Agua residual bruta | C13: ='Cerceda Balance'!AQ59*366 -> 177368.48 | D13: =SUM('Ambas EDAR'!L6:L17) -> 177469 | I13: Agua residual bruta
B14: Polielectrolito | I14: Policloruro de aluminio
B15: Electricidad | I15: Metanol
I16: Electricidad
B26: Salidas en la EDARI de Cerceda (anual) | I26: Salidas en la EDAR de Vedra (anual)
B27: Item | C27: Cantidad | D27: Unidad | I27: Item | J27: Cantidad | K27: Unidad
B28: Agua residual bruta | I28: Agua residual bruta
B29: Arenas | I29: Lodos a gestión
B30: Grasas | I30: CO2
B31: Desbaste | I31: CH4
B32: Lodos deshidratados | I32: N2
B33: CO2 | I33: N2O
B34: CH4
B35: N2
B36: N2O
